<?xml version="1.0" encoding="utf-8"?>
<!-- =================================================================================== -->
<!-- |    This document was autogenerated by xacro from test_rs2.urdf.xacro            | -->
<!-- |    EDITING THIS FILE BY HAND IS NOT RECOMMENDED                                 | -->
<!-- =================================================================================== -->
<robot name="rs2">
  <link name="base_link"/>
  <material name="black">
    <color rgba="0.3 0.3 0.3 1.0"/>
  </material>
  <joint name="rs2_joint" type="fixed">
    <origin rpy="0 0 0" xyz="0 0 0"/>
    <parent link="base_link"/>
    <child link="rs2_base_link"/>
  </joint>
  <link name="rs2_base_link">
    <visual>
      <origin xyz="0.055 0 0.04156"/>
      <geometry>
        <box size="0.112 0.110 0.08312"/>
      </geometry>
      <material name="black"/>
    </visual>
    <collision>
      <origin xyz="0.055 0 0.04156"/>
      <geometry>
        <box size="0.112 0.110 0.08312"/>
      </geometry>
    </collision>
  </link>
  <link name="rs2_1013_base">
    <visual>
      <origin xyz="0 0 0.0316"/>
      <geometry>
        <cylinder length="0.0532" radius="0.046"/>
      </geometry>
      <material name="black"/>
    </visual>
    <visual>
      <origin rpy="1.5707 0 0" xyz="-0.046 0 0.0632"/>
      <geometry>
        <cylinder length="0.092" radius="0.046"/>
      </geometry>
    </visual>
    <collision>
      <origin xyz="0 0 0.0316"/>
      <geometry>
        <cylinder length="0.0532" radius="0.046"/>
      </geometry>
    </collision>
    <collision>
      <origin rpy="1.5707 0 0" xyz="-0.046 0 0.0632"/>
      <geometry>
        <cylinder length="0.092" radius="0.046"/>
      </geometry>
    </collision>
  </link>
  <link name="rs2_1013_to_1015">
    <visual>
      <origin rpy="0 0 0" xyz="-0.046 0 -0.145275"/>
      <geometry>
        <cylinder length="0.28055" radius="0.046"/>
      </geometry>
      <material name="black"/>
    </visual>
    <visual>
      <material name="black"/>
      <origin rpy="1.5707 0 0" xyz="-0.0052 0 -0.29055"/>
      <geometry>
        <cylinder length="0.092" radius="0.041"/>
      </geometry>
    </visual>
    <collision>
      <origin rpy="0 0 0" xyz="-0.046 0 -0.145275"/>
      <geometry>
        <cylinder length="0.28055" radius="0.046"/>
      </geometry>
    </collision>
    <collision>
      <origin rpy="1.5707 0 0" xyz="-0.0052 0 -0.29055"/>
      <geometry>
        <cylinder length="0.092" radius="0.041"/>
      </geometry>
    </collision>
  </link>
  <link name="rs2_1015_Elbow">
    <visual>
      <origin rpy="0 0 0" xyz="0.0402 0 0.048255"/>
      <geometry>
        <cylinder length="0.08645" radius="0.041"/>
      </geometry>
      <material name="black"/>
    </visual>
    <collision>
      <origin rpy="0 0 0" xyz="0.0402 0 0.048255"/>
      <geometry>
        <cylinder length="0.08645" radius="0.041"/>
      </geometry>
    </collision>
  </link>
  <link name="rs2_1015_to_wrist">
    <visual>
      <origin rpy="0 0 0" xyz="0.00 0 0.05712"/>
      <geometry>
        <cylinder length="0.10424" radius="0.041"/>
      </geometry>
      <material name="black"/>
    </visual>
    <visual>
      <origin rpy="1.5707 0 0" xyz="0.0402 0 0.11424"/>
      <geometry>
        <cylinder length="0.092" radius="0.041"/>
      </geometry>
      <material name="orange"/>
    </visual>
    <collision>
      <origin rpy="0 0 0" xyz="0.00 0 0.05712"/>
      <geometry>
        <cylinder length="0.10424" radius="0.041"/>
      </geometry>
    </collision>
    <collision>
      <origin rpy="1.5707 0 0" xyz="0.0402 0 0.11424"/>
      <geometry>
        <cylinder length="0.092" radius="0.041"/>
      </geometry>
    </collision>
  </link>
  <link name="rs2_wrist">
    <visual>
      <origin rpy="0 0 0" xyz="0.0402 0 -0.044315"/>
      <geometry>
        <cylinder length="0.07863" radius="0.041"/>
      </geometry>
      <material name="black"/>
    </visual>
    <collision>
      <origin rpy="0 0 0" xyz="0.0402 0 -0.044315"/>
      <geometry>
        <cylinder length="0.07863" radius="0.041"/>
      </geometry>
    </collision>
  </link>
  <link name="rs2_gripper">
    <visual>
      <origin rpy="0 0 0" xyz="0.0 0 -0.059"/>
      <geometry>
        <cylinder length="0.108" radius="0.041"/>
      </geometry>
      <material name="black"/>
    </visual>
    <visual>
      <origin rpy="0 0 0" xyz="0.0 0 -0.188"/>
      <geometry>
        <box size="0.1 0.09 0.14"/>
      </geometry>
      <material name="black"/>
    </visual>
    <visual>
      <origin rpy="0 0.40 0" xyz="-0.033 0 -0.188"/>
      <geometry>
        <box size="0.05 0.09 0.14"/>
      </geometry>
    </visual>
    <visual>
      <origin rpy="0 -0.40 0" xyz="0.033 0 -0.188"/>
      <geometry>
        <box size="0.05 0.09 0.14"/>
      </geometry>
    </visual>
    <collision>
      <origin rpy="0 0 0" xyz="0.0 0 -0.059"/>
      <geometry>
        <cylinder length="0.108" radius="0.041"/>
      </geometry>
    </collision>
    <collision>
      <origin rpy="0 0 0" xyz="0.0 0 -0.188"/>
      <geometry>
        <box size="0.1 0.09 0.14"/>
      </geometry>
    </collision>
    <collision>
      <origin rpy="0 0.40 0" xyz="-0.033 0 -0.188"/>
      <geometry>
        <box size="0.05 0.09 0.14"/>
      </geometry>
    </collision>
    <collision>
      <origin rpy="0 -0.40 0" xyz="0.033 0 -0.188"/>
      <geometry>
        <box size="0.05 0.09 0.14"/>
      </geometry>
    </collision>
  </link>
  <link name="rs2_RS2_255_1">
        </link>
  <link name="rs2_RS2_255_2">
        </link>
  <link name="rs2_push_rod"/>
  <joint name="rs2_push_rod_joint" type="prismatic">
    <origin rpy="0 0 0" xyz="0 0 -0.118"/>
    <parent link="rs2_gripper"/>
    <child link="rs2_push_rod"/>
    <axis xyz="0 0 1"/>
    <limit effort="10" lower="0" upper="0.035" velocity="10"/>
  </joint>
  <joint name="rs2_gripper_joint_1" type="revolute">
    <parent link="rs2_gripper"/>
    <child link="rs2_RS2_255_2"/>
    <origin rpy="0 0 0" xyz="-0.033 0 -0.118"/>
    <axis xyz="0 1 0"/>
    <limit effort="9.0" lower="0.0" upper="0.5" velocity="0.5"/>
  </joint>
  <joint name="rs2_gripper_joint_2" type="revolute">
    <parent link="rs2_gripper"/>
    <child link="rs2_RS2_255_1"/>
    <origin rpy="0 0 0" xyz="0.033 0 -0.118"/>
    <axis xyz="0 -1 0"/>
    <limit effort="9.0" lower="0.0" upper="0.5" velocity="0.5"/>
    <mimic joint="rs2_gripper_joint_1" multiplier="1" offset="0"/>
  </joint>
  <joint name="rs2_joint_b" type="revolute">
    <parent link="rs2_wrist"/>
    <child link="rs2_gripper"/>
    <origin rpy="0 0 0" xyz="0.040 0 -0.08863"/>
    <axis xyz="0 0 1"/>
    <limit effort="9.0" lower="0.0" upper="6.3" velocity="0.5"/>
  </joint>
  <joint name="rs2_joint_c" type="revolute">
    <parent link="rs2_1015_to_wrist"/>
    <child link="rs2_wrist"/>
    <origin rpy="0 0 0" xyz="0.040 0 0.11424"/>
    <axis xyz="0 -1 0"/>
    <limit effort="9.0" lower="0.0" upper="3.2" velocity="0.5"/>
  </joint>
  <joint name="rs2_joint_d" type="revolute">
    <parent link="rs2_1015_Elbow"/>
    <child link="rs2_1015_to_wrist"/>
    <origin rpy="0 0 0" xyz="0.040 0 0.09645"/>
    <axis xyz="0 0 -1"/>
    <limit effort="9.0" lower="0.0" upper="6.3" velocity="0.5"/>
  </joint>
  <joint name="rs2_joint_e" type="revolute">
    <parent link="rs2_1013_to_1015"/>
    <child link="rs2_1015_Elbow"/>
    <origin rpy="0 0 0" xyz="-0.0052 0 -0.29055"/>
    <axis xyz="0 1 0"/>
    <limit effort="9.0" lower="0.0" upper="3.2" velocity="0.5"/>
  </joint>
  <joint name="rs2_joint_f" type="revolute">
    <parent link="rs2_1013_base"/>
    <child link="rs2_1013_to_1015"/>
    <origin rpy="0 0 0" xyz="-0.046 0 0.0632"/>
    <axis xyz="0 1 0"/>
    <limit effort="9.0" lower="0.0" upper="3.2" velocity="0.5"/>
  </joint>
  <joint name="rs2_joint_g" type="revolute">
    <parent link="rs2_base_link"/>
    <child link="rs2_1013_base"/>
    <origin rpy="0 0 0" xyz="0.0665 0 0.08312"/>
    <axis xyz="0 0 1"/>
    <limit effort="9.0" lower="0.0" upper="6.2" velocity="0.5"/>
  </joint>
</robot>
